Workbook

Sheet Resumen
A1: Resumen de esfuerzo por épica
A3: Épica | B3: Nº HU | C3: SP | D3: Horas sin IA | E3: Horas con IA
A4: 1 – Paciente | B4: =COUNTIF(Historias!$B$2:$B$27,A4) -> 5 | C4: =SUMIFS(Historias!$F$2:$F$27,Historias!$B$2:$B$27,A4) -> 18 | D4: =SUMIFS(Historias!$G$2:$G$27,Historias!$B$2:$B$27,A4) -> 48 | E4: =SUMIFS(Historias!$H$2:$H$27,Historias!$B$2:$B$27,A4) -> 24
A5: 2 – Médico | B5: =COUNTIF(Historias!$B$2:$B$27,A5) -> 7 | C5: =SUMIFS(Historias!$F$2:$F$27,Historias!$B$2:$B$27,A5) -> 29 | D5: =SUMIFS(Historias!$G$2:$G$27,Historias!$B$2:$B$27,A5) -> 80 | E5: =SUMIFS(Historias!$H$2:$H$27,Historias!$B$2:$B$27,A5) -> 40
A6: 3 – Administración y Admisiones | B6: =COUNTIF(Historias!$B$2:$B$27,A6) -> 6 | C6: =SUMIFS(Historias!$F$2:$F$27,Historias!$B$2:$B$27,A6) -> 26 | D6: =SUMIFS(Historias!$G$2:$G$27,Historias!$B$2:$B$27,A6) -> 72 | E6: =SUMIFS(Historias!$H$2:$H$27,Historias!$B$2:$B$27,A6) -> 36
A7: 4 – Administrador del sistema | B7: =COUNTIF(Historias!$B$2:$B$27,A7) -> 8 | C7: =SUMIFS(Historias!$F$2:$F$27,Historias!$B$2:$B$27,A7) -> 43 | D7: =SUMIFS(Historias!$G$2:$G$27,Historias!$B$2:$B$27,A7) -> 122 | E7: =SUMIFS(Historias!$H$2:$H$27,Historias!$B$2:$B$27,A7) -> 61
A8: TOTAL | B8: =SUM(B4:B7) -> 26 | C8: =SUM(C4:C7) -> 116 | D8: =SUM(D4:D7) -> 322 | E8: =SUM(E4:E7) -> 161
A10: Notas
A11: • Una HU por requisito funcional (1 RF : 1 HU : 1 iteración), como propone el enunciado. Revisar si conviene agrupar en módulos Maven más cohesivos.
A12: • La Iteración 0 (Inception) y la Iteración N (integración, empaquetado, manual) no se incluyen: se presupuestan aparte.
A13: • Las horas se calculan desde la hoja Parámetros (equivalencia SP→horas y factor con IA).
A14: • Hojas: Historias (una fila por HU), Tasks (una fila por task, lista para importar a Jira/GitHub), Parámetros.
A15: • Revisión: HU-09, HU-13 y HU-21 se han dividido en HU-25, HU-26 y HU-24 (el SP total no cambia). Vocabulario: "administrativo" pasa a "personal de Admisiones". Ver hojas Trazabilidad y Casos de uso.

Sheet Parámetros
A1: Parámetros de estimación
A2: Celdas en azul = valores editables. Todas las horas del libro se recalculan a partir de ellas.
A4: Puntos de historia (SP) | B4: Horas sin IA
A5: 2 | B5: 4
A6: 3 | B6: 8
A7: 5 | B7: 14
A8: 8 | B8: 24
A9: 13 | B9: 40
A11: Factor de horas con IA respecto a sin IA | B11: 0.5
A12: Supuesto inicial del 50 %; no está medido. Ajustadlo con vuestra velocidad real y descontad el sesgo optimista de la IA.
A14: Leyenda de tipo de task
A15: H | B15: Tarea del ingeniero (análisis, diseño de interfaces, diseño de pruebas)
A16: A | B16: Tarea delegable a un agente de IA, con revisión humana

Sheet Historias
A1: ID | B1: Épica | C1: Nombre | D1: Descripción | E1: Criterios de aceptación | F1: Esfuerzo (SP) | G1: Horas sin IA | H1: Horas con IA | I1: Tasks
A2: HU-01 | B2: 1 – Paciente | C2: Gestionar mis citas | D2: Como paciente, quiero consultar, confirmar, solicitar el cambio o cancelar mis citas, para gestionar mis pruebas sin llamar al hospital. | E2: • Veo la lista de mis citas futuras con prueba, fecha, hora, sala y estado. • Puedo confirmar o cancelar una cita; la cancelación libera el hueco en la agenda. • Puedo solicitar un cambio de fecha; la solicitud queda pendiente para Admisiones y veo su estado. • No puedo cancelar ni modificar citas pasadas ni de otros pacientes. | F2: 5 | G2: =INDEX(Parámetros!$B$5:$B$9,MATCH(F2,Parámetros!$A$5:$A$9,0)) -> 14 | H2: =G2*Parámetros!$B$11 -> 7 | I2: 1. (H) Especificar el caso de uso y los estados de una cita 2. (H) Definir la interfaz del módulo de citas (consulta y cambio de estado) 3. (A) Implementar servicio y repositorio de citas del paciente 4. (A) Implementar vistas de consulta, confirmación, cancelación y solicitud de cambio 5. (H) Diseñar y revisar pruebas unitarias y de integración
A3: HU-02 | B3: 1 – Paciente | C3: Recibir notificaciones y recordatorios | D3: Como paciente, quiero recibir avisos sobre mis citas, la preparación previa y la disponibilidad de informes, para acudir bien preparado y enterarme cuando haya resultados. | E3: • Recibo un recordatorio antes de cada cita con la antelación configurada. • Cuando la prueba exige preparación (ayuno, contraste), el aviso incluye las instrucciones. • Recibo un aviso cuando un informe pasa a estar disponible. • Si cancelo o reprogramo una cita, el recordatorio anterior deja de enviarse. | F3: 5 | G3: =INDEX(Parámetros!$B$5:$B$9,MATCH(F3,Parámetros!$A$5:$A$9,0)) -> 14 | H3: =G3*Parámetros!$B$11 -> 7 | I3: 1. (H) Definir eventos que generan notificación y plantillas de mensaje 2. (H) Diseñar la interfaz de envío (canal desacoplado: correo, push) 3. (A) Implementar el planificador de recordatorios 4. (A) Implementar la bandeja de notificaciones del paciente 5. (H) Diseñar pruebas de los casos de cancelación y reprogramación
A4: HU-03 | B4: 1 – Paciente | C4: Consultar mi historial de pruebas | D4: Como paciente, quiero consultar las pruebas diagnósticas que me han realizado, para tener acceso a mi historial. | E4: • Veo mis pruebas realizadas ordenadas por fecha, con tipo de prueba y estado del informe. • Puedo abrir el informe cuando está disponible. • Solo accedo a mis propios datos; cada acceso queda registrado para auditoría. | F4: 3 | G4: =INDEX(Parámetros!$B$5:$B$9,MATCH(F4,Parámetros!$A$5:$A$9,0)) -> 8 | H4: =G4*Parámetros!$B$11 -> 4 | I4: 1. (H) Especificar el caso de uso y la política de visibilidad de informes 2. (A) Implementar la consulta de historial con filtros por fecha y tipo 3. (A) Implementar la vista de detalle del informe 4. (H) Diseñar pruebas de control de acceso
A5: HU-04 | B5: 1 – Paciente | C5: Enviar incidencias y encuestas de satisfacción | D5: Como paciente, quiero reportar incidencias y valorar la atención recibida, para contribuir a mejorar el servicio. | E5: • Puedo enviar una incidencia con descripción y, opcionalmente, asociarla a una cita. • Tras una prueba completada puedo responder una encuesta de satisfacción una sola vez. • Recibo confirmación del envío y puedo ver el estado de mis incidencias. | F5: 3 | G5: =INDEX(Parámetros!$B$5:$B$9,MATCH(F5,Parámetros!$A$5:$A$9,0)) -> 8 | H5: =G5*Parámetros!$B$11 -> 4 | I5: 1. (H) Definir el modelo de incidencia y el cuestionario de la encuesta 2. (A) Implementar formularios y persistencia 3. (A) Implementar la vista de seguimiento de incidencias 4. (H) Diseñar pruebas de validación de formularios
A6: HU-05 | B6: 1 – Paciente | C6: Consultar guías clínicas y revisiones periódicas | D6: Como paciente, quiero acceder a guías clínicas y a mi calendario de revisiones periódicas, para saber qué pruebas de seguimiento me corresponden y cuándo. | E6: • Puedo consultar las guías asociadas a cada tipo de prueba. • Veo las fechas previstas de mis pruebas de seguimiento. • El contenido de las guías solo lo modifica personal autorizado. | F6: 2 | G6: =INDEX(Parámetros!$B$5:$B$9,MATCH(F6,Parámetros!$A$5:$A$9,0)) -> 4 | H6: =G6*Parámetros!$B$11 -> 2 | I6: 1. (H) Definir la estructura de las guías y su relación con el catálogo 2. (A) Implementar la consulta de guías y del calendario de seguimiento 3. (H) Diseñar pruebas de consulta y preparar contenido de ejemplo
A7: HU-06 | B7: 2 – Médico | C7: Solicitar una prueba diagnóstica | D7: Como médico, quiero prescribir una prueba indicando indicación clínica, justificación y prioridad, para que Admisiones pueda citar al paciente. | E7: • Selecciono paciente y tipo de prueba del catálogo; indicación y justificación son obligatorias. • La prioridad (urgente, preferente, rutinaria) es obligatoria. • El sistema avisa si la prueba tiene restricciones de seguridad o necesita contraste y consentimiento informado. • La petición queda en estado «pendiente de cita» y visible para Admisiones. | F7: 5 | G7: =INDEX(Parámetros!$B$5:$B$9,MATCH(F7,Parámetros!$A$5:$A$9,0)) -> 14 | H7: =G7*Parámetros!$B$11 -> 7 | I7: 1. (H) Especificar el caso de uso y el ciclo de vida de una petición 2. (H) Definir la interfaz entre peticiones y catálogo de pruebas 3. (A) Implementar el formulario y la validación de reglas 4. (A) Implementar la persistencia y la publicación en la lista de pendientes 5. (H) Diseñar pruebas de reglas de seguridad y prioridad
A8: HU-07 | B8: 2 – Médico | C8: Solicitar pruebas de seguimiento periódicas | D8: Como médico, quiero ordenar pruebas con un intervalo de recurrencia, para que se generen automáticamente las futuras necesidades de citación. | E8: • Solo puedo programar seguimiento en pruebas marcadas como aptas para ello. • Defino intervalo y número de repeticiones o fecha final. • El sistema genera las peticiones futuras en las fechas correspondientes. • Puedo suspender o modificar la serie y se actualizan las peticiones futuras. | F8: 5 | G8: =INDEX(Parámetros!$B$5:$B$9,MATCH(F8,Parámetros!$A$5:$A$9,0)) -> 14 | H8: =G8*Parámetros!$B$11 -> 7 | I8: 1. (H) Modelar la recurrencia y sus casos límite 2. (A) Implementar el generador de peticiones futuras 3. (A) Implementar la gestión de series (suspender, modificar) 4. (H) Diseñar pruebas con calendarios y fechas límite
A9: HU-08 | B9: 2 – Médico | C9: Seguir el estado de mis peticiones y ver agendas | D9: Como médico, quiero ver el estado de mis peticiones y las agendas disponibles, para saber cuándo se realizarán las pruebas. | E9: • Veo mis peticiones con estado (pendiente, citada, realizada, informada, cancelada). • Puedo filtrar por paciente, prioridad y estado. • Puedo consultar los huecos libres de agenda por tipo de prueba, sin modificarlos. | F9: 3 | G9: =INDEX(Parámetros!$B$5:$B$9,MATCH(F9,Parámetros!$A$5:$A$9,0)) -> 8 | H9: =G9*Parámetros!$B$11 -> 4 | I9: 1. (H) Especificar los estados y las transiciones permitidas 2. (A) Implementar listado con filtros 3. (A) Implementar la consulta de agenda en solo lectura 4. (H) Diseñar pruebas de filtros y permisos
A10: HU-09 | B10: 2 – Médico | C10: Redactar, revisar y firmar informes diagnósticos | D10: Como médico, quiero redactar, editar, revisar y firmar el informe de una prueba, para emitir el diagnóstico de mis pacientes. | E10: • Guardo borradores, edito y firmo el informe; una vez firmado queda versionado y no se sobrescribe. • Solo accedo a informes de mis pacientes asignados. • Al firmar, se dispara el aviso al paciente (HU-02). | F10: 5 | G10: =INDEX(Parámetros!$B$5:$B$9,MATCH(F10,Parámetros!$A$5:$A$9,0)) -> 14 | H10: =G10*Parámetros!$B$11 -> 7 | I10: 1. (H) Especificar el flujo borrador, revisión y firma 2. (A) Implementar editor de informes y versionado 3. (A) Implementar la firma y el cambio de estado 4. (H) Diseñar pruebas de versionado y permisos
A11: HU-25 | B11: 2 – Médico | C11: Visualizar imágenes DICOM desde el informe | D11: Como médico, quiero abrir las imágenes de la prueba en un visor DICOM web desde el informe, para fundamentar el diagnóstico. | E11: • Abro el visor desde el informe con las imágenes de la prueba. • Solo accedo a imágenes de mis pacientes asignados y cada acceso queda auditado. • Si el PACS no está disponible, veo un mensaje claro y puedo seguir redactando el informe. | F11: 3 | G11: =INDEX(Parámetros!$B$5:$B$9,MATCH(F11,Parámetros!$A$5:$A$9,0)) -> 8 | H11: =G11*Parámetros!$B$11 -> 4 | I11: 1. (H) Definir los requisitos del visor y la política de acceso a imágenes 2. (A) Integrar el visor DICOM web 3. (A) Conectar el visor con la interfaz de imágenes del PACS (HU-24) 4. (H) Diseñar pruebas de control de acceso y de fallo del PACS
A12: HU-10 | B12: 2 – Médico | C12: Registrar la ejecución de la prueba y sus incidencias | D12: Como médico, quiero registrar cómo se ha realizado una prueba y documentar incidencias clínicas u operativas, para dejar trazabilidad. | E12: • Registro hora real, equipo/sala usada y observaciones. • Puedo asociar incidencias (técnica, clínica, paciente ausente) a la ejecución. • La petición pasa a «realizada» al guardar la ejecución. | F12: 3 | G12: =INDEX(Parámetros!$B$5:$B$9,MATCH(F12,Parámetros!$A$5:$A$9,0)) -> 8 | H12: =G12*Parámetros!$B$11 -> 4 | I12: 1. (H) Definir el modelo de ejecución e incidencia 2. (A) Implementar formulario y persistencia 3. (A) Implementar la transición de estado de la petición 4. (H) Diseñar pruebas de estados
A13: HU-11 | B13: 2 – Médico | C13: Consultar métricas operativas de mis peticiones | D13: Como médico, quiero ver tiempos de espera, uso de recursos y cumplimiento de seguimientos, para evaluar cómo se atienden mis peticiones. | E13: • Veo el tiempo medio de espera entre petición y realización, por prioridad. • Veo la utilización de recursos técnicos de mis pruebas. • Veo el porcentaje de seguimientos realizados en plazo. • Los datos se limitan a mis propias peticiones y se pueden filtrar por periodo. | F13: 5 | G13: =INDEX(Parámetros!$B$5:$B$9,MATCH(F13,Parámetros!$A$5:$A$9,0)) -> 14 | H13: =G13*Parámetros!$B$11 -> 7 | I13: 1. (H) Definir las métricas y sus fórmulas 2. (A) Implementar consultas agregadas 3. (A) Implementar el panel con filtros de periodo 4. (H) Verificar los cálculos con datos de prueba
... A27: HU-23 | B27: 4 – Administrador del sistema | C27: Gestionar el catálogo de tipos de prueba | D27: Como administrador, quiero mantener el catálogo de pruebas con sus atributos, para que médicos y administrativos trabajen con información correcta. | E27: • Puedo crear, editar y desactivar tipos de prueba con modalidad, equipo/sala, duración, preparación, contraste y consentimiento, restricciones, prioridad y aptitud para seguimiento. • Una prueba desactivada no se puede solicitar, pero se conserva en el historial. • Los campos obligatorios se validan. | F27: 5 | G27: =INDEX(Parámetros!$B$5:$B$9,MATCH(F27,Parámetros!$A$5:$A$9,0)) -> 14 | H27: =G27*Parámetros!$B$11 -> 7 | I27: 1. (H) Modelar el catálogo y sus atributos 2. (H) Definir la interfaz del catálogo para los demás módulos 3. (A) Implementar CRUD con desactivación lógica 4. (A) Cargar datos iniciales (radiografía, ecografía, mamografía, TC, RM) 5. (H) Diseñar pruebas de validación
C28: TOTAL | F28: =SUM(F2:F27) -> 116 | G28: =SUM(G2:G27) -> 322 | H28: =SUM(H2:H27) -> 161

Sheet Tasks
A1: ID task | B1: HU | C1: Nombre de la HU | D1: Tipo (H/A) | E1: Task
A2: HU-01-T1 | B2: HU-01 | C2: Gestionar mis citas | D2: H | E2: Especificar el caso de uso y los estados de una cita
A3: HU-01-T2 | B3: HU-01 | C3: Gestionar mis citas | D3: H | E3: Definir la interfaz del módulo de citas (consulta y cambio de estado)
A4: HU-01-T3 | B4: HU-01 | C4: Gestionar mis citas | D4: A | E4: Implementar servicio y repositorio de citas del paciente
A5: HU-01-T4 | B5: HU-01 | C5: Gestionar mis citas | D5: A | E5: Implementar vistas de consulta, confirmación, cancelación y solicitud de cambio
A6: HU-01-T5 | B6: HU-01 | C6: Gestionar mis citas | D6: H | E6: Diseñar y revisar pruebas unitarias y de integración
A7: HU-02-T1 | B7: HU-02 | C7: Recibir notificaciones y recordatorios | D7: H | E7: Definir eventos que generan notificación y plantillas de mensaje
A8: HU-02-T2 | B8: HU-02 | C8: Recibir notificaciones y recordatorios | D8: H | E8: Diseñar la interfaz de envío (canal desacoplado: correo, push)
A9: HU-02-T3 | B9: HU-02 | C9: Recibir notificaciones y recordatorios | D9: A | E9: Implementar el planificador de recordatorios
A10: HU-02-T4 | B10: HU-02 | C10: Recibir notificaciones y recordatorios | D10: A | E10: Implementar la bandeja de notificaciones del paciente
A11: HU-02-T5 | B11: HU-02 | C11: Recibir notificaciones y recordatorios | D11: H | E11: Diseñar pruebas de los casos de cancelación y reprogramación
A12: HU-03-T1 | B12: HU-03 | C12: Consultar mi historial de pruebas | D12: H | E12: Especificar el caso de uso y la política de visibilidad de informes
... A112: HU-23-T5 | B112: HU-23 | C112: Gestionar el catálogo de tipos de prueba | D112: H | E112: Diseñar pruebas de validación

Sheet Casos de uso
A1: ID CU | B1: Caso de uso | C1: Tipo | D1: Actor principal | E1: Actores secundarios | F1: HU principal | G1: Otras HU que lo usan | H1: Relaciones | I1: Observaciones
A2: CU-01 | B2: Consultar mis citas | C2: Usuario | D2: Paciente | F2: HU-01
A3: CU-02 | B3: Confirmar cita | C3: Usuario | D3: Paciente | F3: HU-01
A4: CU-03 | B4: Cancelar cita | C4: Usuario | D4: Paciente; Personal de Admisiones | F4: HU-01 | G4: HU-26 | H4: «include» CU-05 | I4: CU compartido con dos actores (generalización): el paciente cancela las suyas y Admisiones cualquiera.
A5: CU-04 | B5: Solicitar cambio de cita | C5: Usuario | D5: Paciente | F5: HU-01 | G5: HU-26 | I5: Genera una solicitud pendiente que resuelve CU-30.
A6: CU-05 | B6: Enviar notificación | C6: Sistema | D6: Planificador (temporizador) | E6: Canal de envío (correo/push) | F6: HU-02 | G6: HU-01; HU-09; HU-13; HU-26 | I6: Transversal: lo incluyen cancelar, reprogramar, asignar y firmar informe.
A7: CU-06 | B7: Consultar bandeja de notificaciones | C7: Usuario | D7: Paciente | F7: HU-02
A8: CU-07 | B8: Consultar historial de pruebas | C8: Usuario | D8: Paciente | F8: HU-03 | H8: «include» CU-08
A9: CU-08 | B9: Consultar informe de una prueba | C9: Usuario | D9: Paciente; Médico | F9: HU-03 | G9: HU-09 | I9: Se reutiliza desde el flujo de informes del médico.
A10: CU-09 | B10: Enviar incidencia | C10: Usuario | D10: Paciente | F10: HU-04
A11: CU-10 | B11: Responder encuesta de satisfacción | C11: Usuario | D11: Paciente | F11: HU-04 | I11: Solo una vez por prueba completada.
A12: CU-11 | B12: Consultar guías clínicas | C12: Usuario | D12: Paciente | F12: HU-05
A13: CU-12 | B13: Consultar calendario de seguimiento | C13: Usuario | D13: Paciente | F13: HU-05 | G13: HU-07
A14: CU-13 | B14: Prescribir prueba diagnóstica | C14: Usuario | D14: Médico | F14: HU-06 | G14: HU-23 | I14: Usa el catálogo (HU-23).
A15: CU-14 | B15: Prescribir seguimiento periódico | C15: Usuario | D15: Médico | F15: HU-07 | H15: «extend» CU-13
A16: CU-15 | B16: Gestionar serie de seguimiento | C16: Usuario | D16: Médico | F16: HU-07 | I16: Suspender o modificar la serie.
A17: CU-16 | B17: Generar peticiones futuras | C17: Sistema | D17: Planificador (temporizador) | F17: HU-07 | G17: HU-15 | I17: Lo dispara el calendario de recurrencia.
A18: CU-17 | B18: Consultar estado de mis peticiones | C18: Usuario | D18: Médico | F18: HU-08
A19: CU-18 | B19: Consultar agenda disponible | C19: Usuario | D19: Médico; Personal de Admisiones | F19: HU-08 | G19: HU-13 | I19: Consulta de solo lectura compartida con Asignar cita.
A20: CU-19 | B20: Redactar informe | C20: Usuario | D20: Médico | F20: HU-09 | G20: HU-25 | H20: «include» CU-21
A21: CU-20 | B21: Revisar y firmar informe | C21: Usuario | D21: Médico | F21: HU-09 | H21: «include» CU-05; «include» CU-21 | I21: Al firmar se avisa al paciente.
A22: CU-21 | B22: Visualizar imágenes de la prueba | C22: Usuario | D22: Médico | E22: RIS/PACS | F22: HU-25 | G22: HU-09 | I22: Incluido desde redactar y revisar informe; usa CU-43.
A23: CU-22 | B23: Registrar ejecución de la prueba | C23: Usuario | D23: Médico | F23: HU-10
A24: CU-23 | B24: Registrar incidencia de ejecución | C24: Usuario | D24: Médico | F24: HU-10 | H24: «extend» CU-22
A25: CU-24 | B25: Consultar métricas operativas del médico | C25: Usuario | D25: Médico | F25: HU-11 | G25: HU-16; HU-22 | I25: Motor de indicadores común con CU-35 y CU-44.
A26: CU-25 | B26: Registrar paciente | C26: Usuario | D26: Personal de Admisiones | E26: HCE / admisión | F26: HU-12 | G26: HU-21
A27: CU-26 | B27: Modificar datos del paciente | C27: Usuario | D27: Personal de Admisiones | F27: HU-12
A28: CU-27 | B28: Dar de baja paciente | C28: Usuario | D28: Personal de Admisiones | F28: HU-12 | I28: Baja lógica.
A29: CU-28 | B29: Asignar cita | C29: Usuario | D29: Personal de Admisiones | F29: HU-13 | H29: «include» CU-18; «include» CU-05
A30: CU-29 | B30: Reprogramar cita | C30: Usuario | D30: Personal de Admisiones | F30: HU-26 | G30: HU-01 | H30: «include» CU-05
A31: CU-30 | B31: Resolver solicitud de cambio de cita | C31: Usuario | D31: Personal de Admisiones | F31: HU-26 | G31: HU-01 | H31: «include» CU-29 | I31: Resuelve la solicitud creada en CU-04.
A32: CU-31 | B32: Gestionar lista de trabajo diaria | C32: Usuario | D32: Personal de Admisiones | F32: HU-14
A33: CU-32 | B33: Gestionar lista de espera | C33: Usuario | D33: Personal de Admisiones | F33: HU-15
A34: CU-33 | B34: Modificar prioridad de una petición | C34: Usuario | D34: Personal de Admisiones | F34: HU-15 | I34: Con justificación registrada.
A35: CU-34 | B35: Proponer hueco liberado | C35: Sistema | D35: Planificador (temporizador) | F35: HU-15 | G35: HU-26 | I35: Se dispara al liberarse un hueco (CU-03, CU-29).
A36: CU-35 | B36: Generar informe operativo | C36: Usuario | D36: Personal de Admisiones | F36: HU-16 | G36: HU-11; HU-22
A37: CU-36 | B37: Configurar parámetros del sistema | C37: Usuario | D37: Administrador del sistema | F37: HU-17
A38: CU-37 | B38: Gestionar roles y permisos | C38: Usuario | D38: Administrador del sistema | F38: HU-18 | G38: HU-20
A39: CU-38 | B39: Registrar acceso a datos clínicos | C39: Sistema | D39: Cualquier usuario autenticado (disparador) | F39: HU-19 | G39: HU-03; HU-09; HU-25 | I39: Transversal: lo invoca toda historia que accede a datos clínicos.
A40: CU-39 | B40: Consultar auditoría | C40: Usuario | D40: Administrador del sistema | F40: HU-19
...

Sheet Trazabilidad
A1: ID HU | B1: Épica | C1: Nombre de la HU | D1: SP | E1: RF propuesto | F1: CU propios | G1: Nº CU propios | H1: Relación HU:CU | I1: CU de otras HU que reutiliza | J1: CU propios que reutilizan otras HU | K1: Depende de (HU) | L1: Bloque sugerido | M1: Observaciones / decisiones pendientes
A2: HU-01 | B2: =INDEX(Historias!$B$2:$B$27,MATCH(A2,Historias!$A$2:$A$27,0)) -> 1 – Paciente | C2: =INDEX(Historias!$C$2:$C$27,MATCH(A2,Historias!$A$2:$A$27,0)) -> Gestionar mis citas | D2: =INDEX(Historias!$F$2:$F$27,MATCH(A2,Historias!$A$2:$A$27,0)) -> 5 | E2: RF-01 | F2: CU-01, CU-02, CU-03, CU-04 | G2: =COUNTIF('Casos de uso'!$F$2:$F$46,A2) -> 4 | H2: =IF(G2=1,"1:1","1:N")&IF(OR(I2<>"",J2<>"")," · compartido","") -> 1:N · compartido | I2: CU-05, CU-29, CU-30 | J2: CU-03 (HU-26), CU-04 (HU-26) | K2: HU-13; HU-20 | L2: 2 | M2: Cuatro funciones → CU-01 a CU-04. La cancelación (CU-03) es compartida con Admisiones; valorar unificar confirmar y cancelar.
A3: HU-02 | B3: =INDEX(Historias!$B$2:$B$27,MATCH(A3,Historias!$A$2:$A$27,0)) -> 1 – Paciente | C3: =INDEX(Historias!$C$2:$C$27,MATCH(A3,Historias!$A$2:$A$27,0)) -> Recibir notificaciones y recordatorios | D3: =INDEX(Historias!$F$2:$F$27,MATCH(A3,Historias!$A$2:$A$27,0)) -> 5 | E3: RF-02 | F3: CU-05, CU-06 | G3: =COUNTIF('Casos de uso'!$F$2:$F$46,A3) -> 2 | H3: =IF(G3=1,"1:1","1:N")&IF(OR(I3<>"",J3<>"")," · compartido","") -> 1:N · compartido | J3: CU-05 (HU-01), CU-05 (HU-09), CU-05 (HU-13), CU-05 (HU-26) | K3: HU-13 | L3: 2 | M3: Notificar es un CU de sistema reutilizado por HU-01, 09, 13 y 26. Implementar como servicio con canal desacoplado.
A4: HU-03 | B4: =INDEX(Historias!$B$2:$B$27,MATCH(A4,Historias!$A$2:$A$27,0)) -> 1 – Paciente | C4: =INDEX(Historias!$C$2:$C$27,MATCH(A4,Historias!$A$2:$A$27,0)) -> Consultar mi historial de pruebas | D4: =INDEX(Historias!$F$2:$F$27,MATCH(A4,Historias!$A$2:$A$27,0)) -> 3 | E4: RF-03 | F4: CU-07, CU-08 | G4: =COUNTIF('Casos de uso'!$F$2:$F$46,A4) -> 2 | H4: =IF(G4=1,"1:1","1:N")&IF(OR(I4<>"",J4<>"")," · compartido","") -> 1:N · compartido | I4: CU-38 | J4: CU-08 (HU-09) | K4: HU-09; HU-20 | L4: 3 | M4: CU-08 (consultar informe) se comparte con el flujo de informes del médico.
A5: HU-04 | B5: =INDEX(Historias!$B$2:$B$27,MATCH(A5,Historias!$A$2:$A$27,0)) -> 1 – Paciente | C5: =INDEX(Historias!$C$2:$C$27,MATCH(A5,Historias!$A$2:$A$27,0)) -> Enviar incidencias y encuestas de satisfacción | D5: =INDEX(Historias!$F$2:$F$27,MATCH(A5,Historias!$A$2:$A$27,0)) -> 3 | E5: RF-04 | F5: CU-09, CU-10 | G5: =COUNTIF('Casos de uso'!$F$2:$F$46,A5) -> 2 | H5: =IF(G5=1,"1:1","1:N")&IF(OR(I5<>"",J5<>"")," · compartido","") -> 1:N | K5: HU-20 | L5: 4
A6: HU-05 | B6: =INDEX(Historias!$B$2:$B$27,MATCH(A6,Historias!$A$2:$A$27,0)) -> 1 – Paciente | C6: =INDEX(Historias!$C$2:$C$27,MATCH(A6,Historias!$A$2:$A$27,0)) -> Consultar guías clínicas y revisiones periódicas | D6: =INDEX(Historias!$F$2:$F$27,MATCH(A6,Historias!$A$2:$A$27,0)) -> 2 | E6: RF-05 | F6: CU-11, CU-12 | G6: =COUNTIF('Casos de uso'!$F$2:$F$46,A6) -> 2 | H6: =IF(G6=1,"1:1","1:N")&IF(OR(I6<>"",J6<>"")," · compartido","") -> 1:N · compartido | J6: CU-12 (HU-07) | K6: HU-07; HU-23 | L6: 4 | M6: El calendario depende de HU-07 y las guías, del catálogo (HU-23).
A7: HU-06 | B7: =INDEX(Historias!$B$2:$B$27,MATCH(A7,Historias!$A$2:$A$27,0)) -> 2 – Médico | C7: =INDEX(Historias!$C$2:$C$27,MATCH(A7,Historias!$A$2:$A$27,0)) -> Solicitar una prueba diagnóstica | D7: =INDEX(Historias!$F$2:$F$27,MATCH(A7,Historias!$A$2:$A$27,0)) -> 5 | E7: RF-06 | F7: CU-13 | G7: =COUNTIF('Casos de uso'!$F$2:$F$46,A7) -> 1 | H7: =IF(G7=1,"1:1","1:N")&IF(OR(I7<>"",J7<>"")," · compartido","") -> 1:1 · compartido | I7: CU-45 | J7: CU-13 (HU-23) | K7: HU-12; HU-18; HU-23 | L7: 2 | M7: Depende del catálogo (HU-23): construir antes.
A8: HU-07 | B8: =INDEX(Historias!$B$2:$B$27,MATCH(A8,Historias!$A$2:$A$27,0)) -> 2 – Médico | C8: =INDEX(Historias!$C$2:$C$27,MATCH(A8,Historias!$A$2:$A$27,0)) -> Solicitar pruebas de seguimiento periódicas | D8: =INDEX(Historias!$F$2:$F$27,MATCH(A8,Historias!$A$2:$A$27,0)) -> 5 | E8: RF-07 | F8: CU-14, CU-15, CU-16 | G8: =COUNTIF('Casos de uso'!$F$2:$F$46,A8) -> 3 | H8: =IF(G8=1,"1:1","1:N")&IF(OR(I8<>"",J8<>"")," · compartido","") -> 1:N · compartido | I8: CU-12 | J8: CU-16 (HU-15) | K8: HU-06 | L8: 3 | M8: CU-14 extiende CU-13; CU-16 lo ejecuta el sistema según el calendario de recurrencia.
A9: HU-08 | B9: =INDEX(Historias!$B$2:$B$27,MATCH(A9,Historias!$A$2:$A$27,0)) -> 2 – Médico | C9: =INDEX(Historias!$C$2:$C$27,MATCH(A9,Historias!$A$2:$A$27,0)) -> Seguir el estado de mis peticiones y ver agendas | D9: =INDEX(Historias!$F$2:$F$27,MATCH(A9,Historias!$A$2:$A$27,0)) -> 3 | E9: RF-08 | F9: CU-17, CU-18 | G9: =COUNTIF('Casos de uso'!$F$2:$F$46,A9) -> 2 | H9: =IF(G9=1,"1:1","1:N")&IF(OR(I9<>"",J9<>"")," · compartido","") -> 1:N · compartido | J9: CU-18 (HU-13) | K9: HU-06; HU-13 | L9: 3
A10: HU-09 | B10: =INDEX(Historias!$B$2:$B$27,MATCH(A10,Historias!$A$2:$A$27,0)) -> 2 – Médico | C10: =INDEX(Historias!$C$2:$C$27,MATCH(A10,Historias!$A$2:$A$27,0)) -> Redactar, revisar y firmar informes diagnósticos | D10: =INDEX(Historias!$F$2:$F$27,MATCH(A10,Historias!$A$2:$A$27,0)) -> 5 | E10: RF-09 | F10: CU-19, CU-20 | G10: =COUNTIF('Casos de uso'!$F$2:$F$46,A10) -> 2 | H10: =IF(G10=1,"1:1","1:N")&IF(OR(I10<>"",J10<>"")," · compartido","") -> 1:N · compartido | I10: CU-05, CU-08, CU-21, CU-38 | J10: CU-19 (HU-25) | K10: HU-06; HU-10 | L10: 3 | M10: Dividida: la visualización de imágenes pasa a HU-25.
A11: HU-10 | B11: =INDEX(Historias!$B$2:$B$27,MATCH(A11,Historias!$A$2:$A$27,0)) -> 2 – Médico | C11: =INDEX(Historias!$C$2:$C$27,MATCH(A11,Historias!$A$2:$A$27,0)) -> Registrar la ejecución de la prueba y sus incidencias | D11: =INDEX(Historias!$F$2:$F$27,MATCH(A11,Historias!$A$2:$A$27,0)) -> 3 | E11: RF-10 | F11: CU-22, CU-23 | G11: =COUNTIF('Casos de uso'!$F$2:$F$46,A11) -> 2 | H11: =IF(G11=1,"1:1","1:N")&IF(OR(I11<>"",J11<>"")," · compartido","") -> 1:N | K11: HU-13 | L11: 3
A12: HU-11 | B12: =INDEX(Historias!$B$2:$B$27,MATCH(A12,Historias!$A$2:$A$27,0)) -> 2 – Médico | C12: =INDEX(Historias!$C$2:$C$27,MATCH(A12,Historias!$A$2:$A$27,0)) -> Consultar métricas operativas de mis peticiones | D12: =INDEX(Historias!$F$2:$F$27,MATCH(A12,Historias!$A$2:$A$27,0)) -> 5 | E12: RF-11 | F12: CU-24 | G12: =COUNTIF('Casos de uso'!$F$2:$F$46,A12) -> 1 | H12: =IF(G12=1,"1:1","1:N")&IF(OR(I12<>"",J12<>"")," · compartido","") -> 1:1 · compartido | I12: CU-35 | J12: CU-24 (HU-16), CU-24 (HU-22) | K12: HU-06; HU-10 | L12: 4 | M12: Motor de indicadores común con HU-16 y HU-22: valorar un único componente de métricas.
A13: HU-12 | B13: =INDEX(Historias!$B$2:$B$27,MATCH(A13,Historias!$A$2:$A$27,0)) -> 3 – Administración y Admisiones | C13: =INDEX(Historias!$C$2:$C$27,MATCH(A13,Historias!$A$2:$A$27,0)) -> Gestionar datos demográficos de pacientes | D13: =INDEX(Historias!$F$2:$F$27,MATCH(A13,Historias!$A$2:$A$27,0)) -> 5 | E13: RF-12 | F13: CU-25, CU-26, CU-27 | G13: =COUNTIF('Casos de uso'!$F$2:$F$46,A13) -> 3 | H13: =IF(G13=1,"1:1","1:N")&IF(OR(I13<>"",J13<>"")," · compartido","") -> 1:N · compartido | I13: CU-41 | J13: CU-25 (HU-21) | K13: HU-18; HU-21 | L13: 2 | M13: Decisión pendiente: fuente de verdad de los datos del paciente (HU-12 frente a HU-21). Registrar en DECISIONS.md.
A14: HU-13 | B14: =INDEX(Historias!$B$2:$B$27,MATCH(A14,Historias!$A$2:$A$27,0)) -> 3 – Administración y Admisiones | C14: =INDEX(Historias!$C$2:$C$27,MATCH(A14,Historias!$A$2:$A$27,0)) -> Asignar citas en la agenda | D14: =INDEX(Historias!$F$2:$F$27,MATCH(A14,Historias!$A$2:$A$27,0)) -> 5 | E14: RF-13 | F14: CU-28 | G14: =COUNTIF('Casos de uso'!$F$2:$F$46,A14) -> 1 | H14: =IF(G14=1,"1:1","1:N")&IF(OR(I14<>"",J14<>"")," · compartido","") -> 1:1 · compartido | I14: CU-05, CU-18 | K14: HU-06; HU-12; HU-17; HU-23 | L14: 2 | M14: Dividida: reprogramar, cancelar y resolver solicitudes pasan a HU-26.
A15: HU-14 | B15: =INDEX(Historias!$B$2:$B$27,MATCH(A15,Historias!$A$2:$A$27,0)) -> 3 – Administración y Admisiones | C15: =INDEX(Historias!$C$2:$C$27,MATCH(A15,Historias!$A$2:$A$27,0)) -> Gestionar listas de trabajo diarias | D15: =INDEX(Historias!$F$2:$F$27,MATCH(A15,Historias!$A$2:$A$27,0)) -> 3 | E15: RF-14 | F15: CU-31 | G15: =COUNTIF('Casos de uso'!$F$2:$F$46,A15) -> 1 | H15: =IF(G15=1,"1:1","1:N")&IF(OR(I15<>"",J15<>"")," · compartido","") -> 1:1 | K15: HU-13 | L15: 3
A16: HU-15 | B16: =INDEX(Historias!$B$2:$B$27,MATCH(A16,Historias!$A$2:$A$27,0)) -> 3 – Administración y Admisiones | C16: =INDEX(Historias!$C$2:$C$27,MATCH(A16,Historias!$A$2:$A$27,0)) -> Gestionar listas de espera y prioridades | D16: =INDEX(Historias!$F$2:$F$27,MATCH(A16,Historias!$A$2:$A$27,0)) -> 5 | E16: RF-15 | F16: CU-32, CU-33, CU-34 | G16: =COUNTIF('Casos de uso'!$F$2:$F$46,A16) -> 3 | H16: =IF(G16=1,"1:1","1:N")&IF(OR(I16<>"",J16<>"")," · compartido","") -> 1:N · compartido | I16: CU-16 | J16: CU-34 (HU-26) | K16: HU-13; HU-17 | L16: 3 | M16: CU-34 se dispara al liberarse un hueco (CU-03, CU-29).
A17: HU-16 | B17: =INDEX(Historias!$B$2:$B$27,MATCH(A17,Historias!$A$2:$A$27,0)) -> 3 – Administración y Admisiones | C17: =INDEX(Historias!$C$2:$C$27,MATCH(A17,Historias!$A$2:$A$27,0)) -> Generar informes operativos | D17: =INDEX(Historias!$F$2:$F$27,MATCH(A17,Historias!$A$2:$A$27,0)) -> 5 | E17: RF-16 | F17: CU-35 | G17: =COUNTIF('Casos de uso'!$F$2:$F$46,A17) -> 1 | H17: =IF(G17=1,"1:1","1:N")&IF(OR(I17<>"",J17<>"")," · compartido","") -> 1:1 · compartido | I17: CU-24 | J17: CU-35 (HU-11), CU-35 (HU-22) | K17: HU-13; HU-15 | L17: 4 | M17: Motor de indicadores común con HU-11 y HU-22.
A18: HU-17 | B18: =INDEX(Historias!$B$2:$B$27,MATCH(A18,Historias!$A$2:$A$27,0)) -> 4 – Administrador del sistema | C18: =INDEX(Historias!$C$2:$C$27,MATCH(A18,Historias!$A$2:$A$27,0)) -> Configurar parámetros del sistema | D18: =INDEX(Historias!$F$2:$F$27,MATCH(A18,Historias!$A$2:$A$27,0)) -> 5 | E18: RF-17 | F18: CU-36 | G18: =COUNTIF('Casos de uso'!$F$2:$F$46,A18) -> 1 | H18: =IF(G18=1,"1:1","1:N")&IF(OR(I18<>"",J18<>"")," · compartido","") -> 1:1 | K18: HU-18 | L18: 1 | M18: Solapa con HU-23 (protocolos) y HU-15 (prioridades): delimitar qué configura cada una.
A19: HU-18 | B19: =INDEX(Historias!$B$2:$B$27,MATCH(A19,Historias!$A$2:$A$27,0)) -> 4 – Administrador del sistema | C19: =INDEX(Historias!$C$2:$C$27,MATCH(A19,Historias!$A$2:$A$27,0)) -> Gestionar roles y permisos | D19: =INDEX(Historias!$F$2:$F$27,MATCH(A19,Historias!$A$2:$A$27,0)) -> 5 | E19: RF-18 | F19: CU-37 | G19: =COUNTIF('Casos de uso'!$F$2:$F$46,A19) -> 1 | H19: =IF(G19=1,"1:1","1:N")&IF(OR(I19<>"",J19<>"")," · compartido","") -> 1:1 · compartido | I19: CU-40 | J19: CU-37 (HU-20) | L19: 1 | M19: HU-20 asigna el rol desde la identidad corporativa y consulta HU-18: construir HU-18 primero con usuarios simulados para evitar dependencia circular.
A20: HU-19 | B20: =INDEX(Historias!$B$2:$B$27,MATCH(A20,Historias!$A$2:$A$27,0)) -> 4 – Administrador del sistema | C20: =INDEX(Historias!$C$2:$C$27,MATCH(A20,Historias!$A$2:$A$27,0)) -> Auditar actividad y accesos a datos clínicos | D20: =INDEX(Historias!$F$2:$F$27,MATCH(A20,Historias!$A$2:$A$27,0)) -> 5 | E20: RF-19 | F20: CU-38, CU-39 | G20: =COUNTIF('Casos de uso'!$F$2:$F$46,A20) -> 2 | H20: =IF(G20=1,"1:1","1:N")&IF(OR(I20<>"",J20<>"")," · compartido","") -> 1:N · compartido | J20: CU-38 (HU-03), CU-38 (HU-09), CU-38 (HU-25) | K20: HU-18 | L20: 1 | M20: CU-38 es transversal: lo invocan todas las historias que acceden a datos clínicos.
A21: HU-20 | B21: =INDEX(Historias!$B$2:$B$27,MATCH(A21,Historias!$A$2:$A$27,0)) -> 4 – Administrador del sistema | C21: =INDEX(Historias!$C$2:$C$27,MATCH(A21,Historias!$A$2:$A$27,0)) -> Acceso con SSO corporativo | D21: =INDEX(Historias!$F$2:$F$27,MATCH(A21,Historias!$A$2:$A$27,0)) -> 5 | E21: RF-20 | F21: CU-40 | G21: =COUNTIF('Casos de uso'!$F$2:$F$46,A21) -> 1 | H21: =IF(G21=1,"1:1","1:N")&IF(OR(I21<>"",J21<>"")," · compartido","") -> 1:1 · compartido | I21: CU-37 | J21: CU-40 (HU-18) | K21: HU-18 | L21: 1 | M21: Registrar la elección de protocolo en DECISIONS.md.
A22: HU-21 | B22: =INDEX(Historias!$B$2:$B$27,MATCH(A22,Historias!$A$2:$A$27,0)) -> 4 – Administrador del sistema | C22: =INDEX(Historias!$C$2:$C$27,MATCH(A22,Historias!$A$2:$A$27,0)) -> Integrar HCE y admisión (FHIR/HL7) | D22: =INDEX(Historias!$F$2:$F$27,MATCH(A22,Historias!$A$2:$A$27,0)) -> 8 | E22: RF-21 | F22: CU-41, CU-42 | G22: =COUNTIF('Casos de uso'!$F$2:$F$46,A22) -> 2 | H22: =IF(G22=1,"1:1","1:N")&IF(OR(I22<>"",J22<>"")," · compartido","") -> 1:N · compartido | I22: CU-25 | J22: CU-41 (HU-12), CU-42 (HU-24) | L22: 2 | M22: Dividida: la parte DICOM pasa a HU-24.
A23: HU-22 | B23: =INDEX(Historias!$B$2:$B$27,MATCH(A23,Historias!$A$2:$A$27,0)) -> 4 – Administrador del sistema | C23: =INDEX(Historias!$C$2:$C$27,MATCH(A23,Historias!$A$2:$A$27,0)) -> Estadísticas globales e informes de uso | D23: =INDEX(Historias!$F$2:$F$27,MATCH(A23,Historias!$A$2:$A$27,0)) -> 5 | E23: RF-22 | F23: CU-44 | G23: =COUNTIF('Casos de uso'!$F$2:$F$46,A23) -> 1 | H23: =IF(G23=1,"1:1","1:N")&IF(OR(I23<>"",J23<>"")," · compartido","") -> 1:1 · compartido | I23: CU-24, CU-35 | K23: HU-13; HU-19 | L23: 4 | M23: Motor de indicadores común con HU-11 y HU-16.
A24: HU-23 | B24: =INDEX(Historias!$B$2:$B$27,MATCH(A24,Historias!$A$2:$A$27,0)) -> 4 – Administrador del sistema | C24: =INDEX(Historias!$C$2:$C$27,MATCH(A24,Historias!$A$2:$A$27,0)) -> Gestionar el catálogo de tipos de prueba | D24: =INDEX(Historias!$F$2:$F$27,MATCH(A24,Historias!$A$2:$A$27,0)) -> 5 | E24: RF-23 | F24: CU-45 | G24: =COUNTIF('Casos de uso'!$F$2:$F$46,A24) -> 1 | H24: =IF(G24=1,"1:1","1:N")&IF(OR(I24<>"",J24<>"")," · compartido","") -> 1:1 · compartido | I24: CU-13 | J24: CU-45 (HU-06) | K24: HU-18 | L24: 1 | M24: Un único CU de gestión con flujos alternativos; alternativa: tres CU.
A25: HU-24 | B25: =INDEX(Historias!$B$2:$B$27,MATCH(A25,Historias!$A$2:$A$27,0)) -> 4 – Administrador del sistema | C25: =INDEX(Historias!$C$2:$C$27,MATCH(A25,Historias!$A$2:$A$27,0)) -> Integrar RIS/PACS (DICOM) | D25: =INDEX(Historias!$F$2:$F$27,MATCH(A25,Historias!$A$2:$A$27,0)) -> 5 | E25: RF-21 (compartido con HU-21) | F25: CU-43 | G25: =COUNTIF('Casos de uso'!$F$2:$F$46,A25) -> 1 | H25: =IF(G25=1,"1:1","1:N")&IF(OR(I25<>"",J25<>"")," · compartido","") -> 1:1 · compartido | I25: CU-42 | J25: CU-43 (HU-25) | L25: 3 | M25: Nueva (división de HU-21). Su interfaz es el contrato que usa HU-25.
A26: HU-25 | B26: =INDEX(Historias!$B$2:$B$27,MATCH(A26,Historias!$A$2:$A$27,0)) -> 2 – Médico | C26: =INDEX(Historias!$C$2:$C$27,MATCH(A26,Historias!$A$2:$A$27,0)) -> Visualizar imágenes DICOM desde el informe | D26: =INDEX(Historias!$F$2:$F$27,MATCH(A26,Historias!$A$2:$A$27,0)) -> 3 | E26: RF-09 (compartido con HU-09) | F26: CU-21 | G26: =COUNTIF('Casos de uso'!$F$2:$F$46,A26) -> 1 | H26: =IF(G26=1,"1:1","1:N")&IF(OR(I26<>"",J26<>"")," · compartido","") -> 1:1 · compartido | I26: CU-19, CU-38, CU-43 | J26: CU-21 (HU-09) | K26: HU-09; HU-24 | L26: 3 | M26: Nueva (división de HU-09). Depende del adaptador PACS (HU-24).
A27: HU-26 | B27: =INDEX(Historias!$B$2:$B$27,MATCH(A27,Historias!$A$2:$A$27,0)) -> 3 – Administración y Admisiones | C27: =INDEX(Historias!$C$2:$C$27,MATCH(A27,Historias!$A$2:$A$27,0)) -> Reprogramar y cancelar citas y resolver solicitudes de cambio | D27: =INDEX(Historias!$F$2:$F$27,MATCH(A27,Historias!$A$2:$A$27,0)) -> 3 | E27: RF-13 (compartido con HU-13) | F27: CU-29, CU-30 | G27: =COUNTIF('Casos de uso'!$F$2:$F$46,A27) -> 2 | H27: =IF(G27=1,"1:1","1:N")&IF(OR(I27<>"",J27<>"")," · compartido","") -> 1:N · compartido | I27: CU-03, CU-04, CU-05, CU-34 | J27: CU-29 (HU-01), CU-30 (HU-01) | K27: HU-01; HU-13 | L27: 2 | M27: Nueva (división de HU-13). Reutiliza CU-03 y CU-04 de HU-01.
A28: =COUNTA(A2:A27) -> 26 | C28: TOTAL | D28: =SUM(D2:D27) -> 116 | G28: =SUM(G2:G27) -> 45 | H28: =TEXT(G28/A28,"0.00")&" CU por HU" -> 1.73 CU por HU
A30: Notas
A31: • El número de CU por historia es 1 o más (1:1 o 1:N). "Compartido" indica que algún CU propio o ajeno se reutiliza entre historias (N:M).
A32: • RF propuesto: un RF por historia original; las historias nacidas de una división (HU-24, HU-25, HU-26) comparten el RF de su origen (N:1).
A33: • Las columnas de listas de CU son texto: se actualizan a mano si cambia la hoja Casos de uso. "Nº CU propios" sí se recalcula.
A34: • Bloques sugeridos (no son iteraciones UP cerradas): 1 base transversal, 2 núcleo de citación, 3 ejecución e informes, 4 explotación y complementos.
A35: • Las dependencias son una propuesta de trabajo y deben ratificarse en la planificación de iteraciones.

Sheet Plantilla CU
A1: Plantilla de especificación de caso de uso
A2: Una ficha por caso de uso. La columna C muestra un ejemplo (CU-03) para ilustrar el nivel de detalle esperado; copiad A:B para cada CU nuevo.
A4: Campo | B4: Qué escribir | C4: Ejemplo: CU-03 Cancelar cita
A5: ID / versión / iteración | B5: CU-XX · versión · iteración UP en la que se realiza | C5: CU-03 · v0.1 · por asignar
A6: Trazabilidad | B6: HU principal y otras HU que lo usan; RF asociado | C6: HU-01 (principal), HU-26 · RF-01
A7: Objetivo | B7: Qué consigue el actor, en una frase | C7: Anular una cita futura y liberar el hueco de agenda.
A8: Actor principal | B8: Rol que inicia el caso de uso | C8: Paciente (sus citas) o Personal de Admisiones (cualquier cita)
A9: Actores secundarios | B9: Otros roles y sistemas externos (SSO, HCE, RIS/PACS, planificador) | C9: Servicio de notificaciones
A10: Relaciones | B10: «include», «extend», generalización de actores | C10: «include» CU-05 Enviar notificación. La liberación del hueco dispara CU-34.
A11: Precondiciones | B11: Estado del sistema y del actor antes de empezar | C11: El actor está autenticado. La cita existe, es futura y no está cancelada. El paciente solo puede cancelar citas propias.
A12: Disparador | B12: Evento que inicia el caso de uso | C12: El actor selecciona «Cancelar» sobre una cita.
A13: Flujo principal | B13: Pasos numerados, un único camino exitoso, alternando actor y sistema | C13: 1. El actor selecciona una cita futura. 2. El sistema muestra sus datos y pide confirmación. 3. El actor confirma. 4. El sistema pasa la cita a «cancelada» y libera el hueco. 5. El sistema registra la acción en auditoría y notifica al paciente (CU-05). 6. El sistema muestra la confirmación.
A14: Flujos alternativos | B14: Variantes válidas del objetivo: paso de origen y paso de retorno | C14: A1 (paso 3): el actor no confirma; el sistema vuelve a la lista sin cambios. A2 (paso 3, Admisiones): el actor indica el motivo de la cancelación y continúa en el paso 4.
A15: Excepciones | B15: Fallos o violaciones de precondición y respuesta del sistema | C15: E1 (paso 1): la cita es pasada o ajena; el sistema deniega la operación. E2 (paso 4): falla la liberación del hueco; no se cancela y se informa del error. E3 (paso 5): falla la notificación; la cita queda cancelada y el aviso se reintenta.
... A18: Supuestos y decisiones | B18: Referencia a DECISIONS.md | C18: Pendiente: antelación mínima de cancelación.
